Traceback (most recent call last):
  File "/usr/local/lib/python3.8/dist-packages/jupyter_cache/executors/utils.py", line 51, in single_nb_execution
    executenb(
  File "/usr/local/lib/python3.8/dist-packages/nbclient/client.py", line 1204, in execute
    return NotebookClient(nb=nb, resources=resources, km=km, **kwargs).execute()
  File "/usr/local/lib/python3.8/dist-packages/nbclient/util.py", line 84, in wrapped
    return just_run(coro(*args, **kwargs))
  File "/usr/local/lib/python3.8/dist-packages/nbclient/util.py", line 62, in just_run
    return loop.run_until_complete(coro)
  File "/usr/lib/python3.8/asyncio/base_events.py", line 616, in run_until_complete
    return future.result()
  File "/usr/local/lib/python3.8/dist-packages/nbclient/client.py", line 663, in async_execute
    await self.async_execute_cell(
  File "/usr/local/lib/python3.8/dist-packages/nbclient/client.py", line 965, in async_execute_cell
    await self._check_raise_for_error(cell, cell_index, exec_reply)
  File "/usr/local/lib/python3.8/dist-packages/nbclient/client.py", line 862, in _check_raise_for_error
    raise CellExecutionError.from_cell_and_msg(cell, exec_reply_content)
nbclient.exceptions.CellExecutionError: An error occurred while executing the following cell:
------------------
# dataframe
target_data = df_petal_width_ef
target_data
------------------

[0;31m[0m
[0;31mNameError[0mTraceback (most recent call last)
[0;32m<ipython-input-69-2e81df6e5ff5>[0m in [0;36m<module>[0;34m[0m
[1;32m      1[0m [0;31m# dataframe[0m[0;34m[0m[0;34m[0m[0;34m[0m[0m
[0;32m----> 2[0;31m [0mtarget_data[0m [0;34m=[0m [0mdf_petal_width_ef[0m[0;34m[0m[0;34m[0m[0m
[0m[1;32m      3[0m [0mtarget_data[0m[0;34m[0m[0;34m[0m[0m

[0;31mNameError[0m: name 'df_petal_width_ef' is not defined
NameError: name 'df_petal_width_ef' is not defined

